Workbook

Sheet Sheet1
B1: 西方传统名称 | C1: 中国 | D1: 西方传统名称 | E1: 拜耳命名法 | F1: 备注
A2: m_cBody->Append(_T("Sun")); | B2: Sun | C2: 星期日 | D2: Sun
A3: m_cBody->Append(_T("Moon")); | B3: Moon | C3: 月亮 | D3: Moon
A4: m_cBody->Append(_T("Mercury")); | B4: Mercury | C4: 水星 | D4: Mercury
A5: m_cBody->Append(_T("Venus")); | B5: Venus | C5: 金星 | D5: Venus
A6: m_cBody->Append(_T("Mars")); | B6: Mars | C6: 火星 | D6: Mars
A7: m_cBody->Append(_T("Jupiter")); | B7: Jupiter | C7: 木星 | D7: Jupiter
A8: m_cBody->Append(_T("Saturn")); | B8: Saturn | C8: 土星 | D8: Saturn
C9: 维基百科 | E9: https://zh.wikipedia.org/
A10: m_cBody->Append(_T("Acamar")); | B10: Acamar | C10: 天园六 | D10: Acamar | E10: 波江座θ
A11: m_cBody->Append(_T("Achernar")); | B11: Achernar | C11: 水委一 | D11: Achernar | E11: 波江座α
A12: m_cBody->Append(_T("Acrux")); | B12: Acrux | C12: 十字架二 | D12: Acrux | E12: 南十字座α
A13: m_cBody->Append(_T("Adhara")); | B13: Adhara | C13: 弧矢七 | D13: Adhara | E13: 大犬座ε
A14: m_cBody->Append(_T("Alioth")); | B14: Alioth | C14: 玉衡 | D14: Alioth | E14: 大熊座ε
A15: m_cBody->Append(_T("Alkaid")); | B15: Alkaid | C15: 摇光 | D15: Alkaid | E15: 大熊座η | F15: 瑶光
A16: m_cBody->Append(_T("Aldebaran")); | B16: Aldebaran | C16: 毕宿五 | D16: Aldebaran | E16: 金牛座α
A17: m_cBody->Append(_T("Al Na'ir")); | B17: Al Na'ir | C17: 鹤一 | D17: Al Na'ir | E17: 天鹤座α
A18: m_cBody->Append(_T("Alnilam")); | B18: Alnilam | C18: 参宿二 | D18: Alnilam | E18: 猎户座ε
A19: m_cBody->Append(_T("Alphard")); | B19: Alphard | C19: 星宿一 | D19: Alphard | E19: 长蛇α
A20: m_cBody->Append(_T("Alphecca")); | B20: Alphecca | C20: 贯索四 | D20: Alphecca | E20: 北冕座α
A21: m_cBody->Append(_T("Alpheratz")); | B21: Alpheratz | C21: 壁宿二 | D21: Alpheratz | E21: 仙女α | F21: 1
A22: m_cBody->Append(_T("Altair")); | B22: Altair | C22: 河鼓二 | D22: Altair | E22: 天鹰座α | F22: 牛郎星/河鼓二
A23: m_cBody->Append(_T("Ankaa")); | B23: Ankaa | C23: 火鸟六 | D23: Ankaa | E23: 凤凰座α
A24: m_cBody->Append(_T("Antares")); | B24: Antares | C24: 心宿二 | D24: Antares | E24: 天蝎座α
A25: m_cBody->Append(_T("Arcturus")); | B25: Arcturus | C25: 大角 | D25: Arcturus | E25: 牧夫座α | F25: 大角星
A26: m_cBody->Append(_T("Atria")); | B26: Atria | C26: 三角形三 | D26: Atria | E26: 南三角座α
A27: m_cBody->Append(_T("Avior")); | B27: Avior | C27: 海石一 | D27: Avior | E27: 船底座ε
A28: m_cBody->Append(_T("Bellatrix")); | B28: Bellatrix | C28: 参宿五 | D28: Bellatrix | E28: 猎户座γ
A29: m_cBody->Append(_T("Betelgeuse")); | B29: Betelgeuse | C29: 参宿四 | D29: Betelgeuse | E29: 猎户α
A30: m_cBody->Append(_T("Canopus")); | B30: Canopus | C30: 老人 | D30: Canopus | E30: 船底座α | F30: 老人星
A31: m_cBody->Append(_T("Capella")); | B31: Capella | C31: 五车二 | D31: Capella | E31: 御夫座α
A32: m_cBody->Append(_T("Deneb")); | B32: Deneb | C32: 天津四 | D32: Deneb | E32: 天鹅座α
A33: m_cBody->Append(_T("Denebola")); | B33: Denebola | C33: 五帝座一 | D33: Denebola | E33: 狮子座β
A34: m_cBody->Append(_T("Diphda")); | B34: Diphda | C34: 土司空 | D34: Diphda | E34: 鲸鱼β | F34: 7
A35: m_cBody->Append(_T("Dubhe")); | B35: Dubhe | C35: 天枢 | D35: Dubhe | E35: 大熊α
A36: m_cBody->Append(_T("Eltanin")); | B36: Eltanin | C36: 天棓四 | D36: Eltanin | E36: 天龙座γ
A37: m_cBody->Append(_T("Elnath")); | B37: Elnath | C37: 五车五 | D37: Elnath | E37: 金牛座β
A38: m_cBody->Append(_T("Enif")); | B38: Enif | C38: 危宿三 | D38: Enif | E38: 飞马座ε
A39: m_cBody->Append(_T("Fomalhaut")); | B39: Fomalhaut | C39: 北落师门 | D39: Fomalhaut | E39: 南鱼座α
A40: m_cBody->Append(_T("Gacrux")); | B40: Gacrux | C40: 十字架一 | D40: Gacrux | E40: 南十字γ
...

Sheet Sheet2
A1: =VLOOKUP(E1,Sheet1!C:D,2,FALSE) -> Alpheratz | B1: 1 | C1: 仙女 | D1: α | E1: 壁宿二
A2: =VLOOKUP(E2,Sheet1!C:D,2,FALSE) -> #N/A | B2: 2 | C2: 仙后 | D2: β | E2: 王良一
A3: =VLOOKUP(E3,Sheet1!C:D,2,FALSE) -> Diphda | B3: 7 | C3: 鲸鱼 | D3: β | E3: 土司空
A4: =VLOOKUP(E4,Sheet1!C:D,2,FALSE) -> Achernar | B4: 11 | C4: 波江 | D4: α | E4: 水委一
A5: =VLOOKUP(E5,Sheet1!C:D,2,FALSE) -> #N/A | B5: 15 | C5: 仙女 | D5: γ | E5: 天大将军一
A6: =VLOOKUP(E6,Sheet1!C:D,2,FALSE) -> Hamal | B6: 16 | C6: 白羊 | D6: α | E6: 娄宿三
A7: =VLOOKUP(E7,Sheet1!C:D,2,FALSE) -> Acamar | B7: 17 | C7: 波江 | D7: θ | E7: 天园六
A8: =VLOOKUP(E8,Sheet1!C:D,2,FALSE) -> Menkar | B8: 18 | C8: 鲸鱼 | D8: α | E8: 天囷一
A9: =VLOOKUP(E9,Sheet1!C:D,2,FALSE) -> Mirfak | B9: 20 | C9: 英仙 | D9: α | E9: 天船三
A10: =VLOOKUP(E10,Sheet1!C:D,2,FALSE) -> Aldebaran | B10: 24 | C10: 金牛 | D10: α | E10: 毕宿五
A11: =VLOOKUP(E11,Sheet1!C:D,2,FALSE) -> Rigel | B11: 27 | C11: 猎户 | D11: β | E11: 参宿七
A12: =VLOOKUP(E12,Sheet1!C:D,2,FALSE) -> Capella | B12: 28 | C12: 御夫 | D12: α | E12: 五车二
... A44: =VLOOKUP(E44,Sheet1!C:D,2,FALSE) -> Polaris | B44: 159 | C44: 小熊 | D44: α | E44: 北极星
